Workbook

Sheet PROJECT 1

Sheet Orders
A1: Order # | B1: Order Date | C1: Country | D1: Client ID | E1: Product ID | F1: Product Name | G1: Quantity | H1: Unit Price | I1: Revenue | K1: Country | L1: Orders
A2: 540546 | B2: 43474 | C2: Portugal | D2: 12766 | E2: 22740 | F2: =VLOOKUP(Orders[[#This Row],[Product ID]],Products!A:B,2,0) -> Polkadot Pen | G2: 48 | H2: 0.85 | I2: 40.8 | K2: United Kingdom | L2: =COUNTIFS(C:C,K2,I:I,">=100") -> 3
A3: 541115 | B3: 43478 | C3: Italy | D3: 12578 | E3: 21260 | F3: =VLOOKUP(Orders[[#This Row],[Product ID]],Products!A:B,2,0) -> First Aid Tin | G3: 6 | H3: 3.25 | I3: 19.5
A4: 541115 | B4: 43478 | C4: Italy | D4: 12578 | E4: 22190 | F4: =VLOOKUP(Orders[[#This Row],[Product ID]],Products!A:B,2,0) -> Local Cafe Mug | G4: 12 | H4: 2.1 | I4: 25.2
A5: 541224 | B5: 43479 | C5: Germany | D5: 12474 | E5: 21025 | F5: =VLOOKUP(Orders[[#This Row],[Product ID]],Products!A:B,2,0) -> Space Frog | G5: 10 | H5: 1.25 | I5: 12.5
A6: 541269 | B6: 43482 | C6: Germany | D6: 12626 | E6: 22174 | F6: =VLOOKUP(Orders[[#This Row],[Product ID]],Products!A:B,2,0) -> Photo Cube | G6: 12 | H6: 1.65 | I6: 19.8
A7: 541509 | B7: 43483 | C7: United Kingdom | D7: 13263 | E7: 22694 | F7: =VLOOKUP(Orders[[#This Row],[Product ID]],Products!A:B,2,0) -> Wicker Star | G7: 1 | H7: 2.1 | I7: 2.1
A8: 541631 | B8: 43485 | C8: France | D8: 12637 | E8: 22174 | F8: =VLOOKUP(Orders[[#This Row],[Product ID]],Products!A:B,2,0) -> Photo Cube | G8: 12 | H8: 1.65 | I8: 19.8
A9: 541711 | B9: 43486 | C9: Netherlands | D9: 14646 | E9: 22653 | F9: =VLOOKUP(Orders[[#This Row],[Product ID]],Products!A:B,2,0) -> Button Box | G9: 10 | H9: 1.95 | I9: 19.5
A10: 542080 | B10: 43490 | C10: Germany | D10: 13815 | E10: 20713 | F10: =VLOOKUP(Orders[[#This Row],[Product ID]],Products!A:B,2,0) -> Jumbo Bag Owls | G10: 10 | H10: 1.95 | I10: 19.5
A11: 542080 | B11: 43490 | C11: Germany | D11: 13815 | E11: 22740 | F11: =VLOOKUP(Orders[[#This Row],[Product ID]],Products!A:B,2,0) -> Polkadot Pen | G11: 48 | H11: 0.85 | I11: 40.8
A12: 542080 | B12: 43490 | C12: Germany | D12: 13815 | E12: 22741 | F12: =VLOOKUP(Orders[[#This Row],[Product ID]],Products!A:B,2,0) -> Funky Diva Pen | G12: 48 | H12: 0.85 | I12: 40.8
A13: 542371 | B13: 43492 | C13: Germany | D13: 12468 | E13: 62018 | F13: =VLOOKUP(Orders[[#This Row],[Product ID]],Products!A:B,2,0) -> Sombrero | G13: 6 | H13: 1.95 | I13: 11.7
A14: 542428 | B14: 43493 | C14: Sweden | D14: 17404 | E14: 21260 | F14: =VLOOKUP(Orders[[#This Row],[Product ID]],Products!A:B,2,0) -> First Aid Tin | G14: 48 | H14: 3.25 | I14: 156
... A201: 581476 | B201: 43808 | C201: Norway | D201: 12433 | E201: 22197 | F201: =VLOOKUP(Orders[[#This Row],[Product ID]],Products!A:B,2,0) -> Popcorn Holder | G201: 100 | H201: 0.72 | I201: 72

Sheet Products
A1: Product ID | B1: Product Name
A2: 20713 | B2: Jumbo Bag Owls
A3: 21025 | B3: Space Frog
A4: 21116 | B4: Owl Doorstop
A5: 21260 | B5: First Aid Tin
A6: 21888 | B6: Bingo Set
A7: 22174 | B7: Photo Cube
A8: 22190 | B8: Local Cafe Mug
A9: 22197 | B9: Popcorn Holder
A10: 22653 | B10: Button Box
A11: 22694 | B11: Wicker Star
A12: 22740 | B12: Polkadot Pen
A13: 22741 | B13: Funky Diva Pen
... A15: 62018 | B15: Sombrero

Sheet Countries
A1: Country | B1: Orders
A2: Austria | B2: 2
A3: Belgium | B3: 12
A4: Denmark | B4: 2
A5: Finland | B5: 3
A6: France | B6: 32
A7: Germany | B7: 44
A8: Italy | B8: 7
A9: Netherlands | B9: 12
A10: Norway | B10: 4
A11: Portugal | B11: 9
A12: Spain | B12: 14
A13: Sweden | B13: 4
... A15: United Kingdom | B15: 48

Sheet Warehouse Extension
A1: Mortgage Payments
A2: Loan Balance | B2: 250000
A3: Annual Interest Rate | B3: 0.045
A4: Term Length (yrs) | B4: 30
A5: Monthly Payment | B5: =PMT(B3/12,B4*12,B2,,1) -> -1261.9808

Sheet Summary Chart
A1: Months | B1: Sum of Revenue
A2: Jan | B2: 459.8
A3: Feb | B3: 1306.65
A4: Mar | B4: 299.1
A5: Apr | B5: 139.5
A6: May | B6: 202.1
A7: Jun | B7: 1211.4
A8: Jul | B8: 518.65
A9: Aug | B9: 574.15
A10: Sep | B10: 1161.72
A11: Oct | B11: 504.09
A12: Nov | B12: 678.42
A13: Dec | B13: 117.9
A14: Grand Total | B14: 7173.48

Sheet PROJECT 2

Sheet Team Selector
C2: MLB Beer Prices
B6: Team | C6: Philadelphia Phillies
B8: Price | C8: =IFERROR(INDEX('Beer Prices'!$A$1:$E$31,MATCH('Team Selector'!$C$6,'Beer Prices'!$A$1:$A$31,0),MATCH('Team Selector'!$B8,'Beer Prices'!$A$1:$E$1,0)),"-") -> 6
B9: Size | C9: =IFERROR(INDEX('Beer Prices'!$A$1:$E$31,MATCH('Team Selector'!$C$6,'Beer Prices'!$A$1:$A$31,0),MATCH('Team Selector'!$B9,'Beer Prices'!$A$1:$E$1,0)),"-") -> 12
B11: Price per Ounce | C11: =IFERROR(C8/C9,"-") -> 0.5

Sheet Beer Prices
A1: Team | B1: Nickname | C1: City | D1: Price | E1: Size
A2: Arizona Diamondbacks | B2: Diamondbacks | C2: Arizona | D2: 4 | E2: 14
A3: Atlanta Braves | B3: Braves | C3: Atlanta | D3: 5 | E3: 12
A4: Baltimore Orioles | B4: Orioles | C4: Baltimore | D4: 4 | E4: 12
A5: Boston Red Sox | B5: Red Sox | C5: Boston | D5: 8 | E5: 12
A6: Chicago Cubs | B6: Cubs | C6: Chicago | D6: 9 | E6: 20
A7: Chicago White Sox | B7: White Sox | C7: Chicago | D7: 7 | E7: 16
A8: Cincinnati Reds | B8: Reds | C8: Cincinnati | D8: 6.25 | E8: 14
A9: Cleveland Indians | B9: Indians | C9: Cleveland | D9: 5 | E9: 12
A10: Colorado Rockies | B10: Rockies | C10: Colorado | D10: 3 | E10: 12
A11: Detroit Tigers | B11: Tigers | C11: Detroit | D11: 5 | E11: 12
A12: Houston Astros | B12: Astros | C12: Houston | D12: 6 | E12: 14
A13: Kansas City Royals | B13: Royals | C13: Kansas City | D13: 4 | E13: 12
... A31: Washington Nationals | B31: Nationals | C31: Washington | D31: 7 | E31: 14

Sheet Price per Ounce
A1: Team | B1: 2013 | C1: 2014 | D1: 2015 | E1: 2016 | F1: 2018 | G1: Change
A2: Arizona Diamondbacks | B2: 0.29 | C2: 0.29 | D2: 0.29 | E2: 0.29 | F2: 0.29 | G2: =IF(PricePerOunce[[#This Row],[2018]]=PricePerOunce[[#This Row],[2013]],"None",IF(OR(PricePerOunce[[#This Row],[2018]]>PricePerOunce[[#This Row],[2016]],PricePerOunce[[#This Row],[2018]]>AVERAGE(PricePerOunce[[#This Row],[2013]:[2016]])),"Increase","Decrease")) -> None
A3: Atlanta Braves | B3: 0.45 | C3: 0.45 | D3: 0.45 | E3: 0.48 | F3: 0.42 | G3: =IF(PricePerOunce[[#This Row],[2018]]=PricePerOunce[[#This Row],[2013]],"None",IF(OR(PricePerOunce[[#This Row],[2018]]>PricePerOunce[[#This Row],[2016]],PricePerOunce[[#This Row],[2018]]>AVERAGE(PricePerOunce[[#This Row],[2013]:[2016]])),"Increase","Decrease")) -> Decrease
A4: Baltimore Orioles | B4: 0.38 | C4: 0.42 | D4: 0.42 | E4: 0.42 | F4: 0.33 | G4: =IF(PricePerOunce[[#This Row],[2018]]=PricePerOunce[[#This Row],[2013]],"None",IF(OR(PricePerOunce[[#This Row],[2018]]>PricePerOunce[[#This Row],[2016]],PricePerOunce[[#This Row],[2018]]>AVERAGE(PricePerOunce[[#This Row],[2013]:[2016]])),"Increase","Decrease")) -> Decrease
A5: Boston Red Sox | B5: 0.6 | C5: 0.65 | D5: 0.65 | E5: 0.65 | F5: 0.67 | G5: =IF(PricePerOunce[[#This Row],[2018]]=PricePerOunce[[#This Row],[2013]],"None",IF(OR(PricePerOunce[[#This Row],[2018]]>PricePerOunce[[#This Row],[2016]],PricePerOunce[[#This Row],[2018]]>AVERAGE(PricePerOunce[[#This Row],[2013]:[2016]])),"Increase","Decrease")) -> Increase
A6: Chicago Cubs | B6: 0.45 | C6: 0.47 | D6: 0.47 | E6: 0.47 | F6: 0.45 | G6: =IF(PricePerOunce[[#This Row],[2018]]=PricePerOunce[[#This Row],[2013]],"None",IF(OR(PricePerOunce[[#This Row],[2018]]>PricePerOunce[[#This Row],[2016]],PricePerOunce[[#This Row],[2018]]>AVERAGE(PricePerOunce[[#This Row],[2013]:[2016]])),"Increase","Decrease")) -> None
A7: Chicago White Sox | B7: 0.41 | C7: 0.41 | D7: 0.41 | E7: 0.41 | F7: 0.44 | G7: =IF(PricePerOunce[[#This Row],[2018]]=PricePerOunce[[#This Row],[2013]],"None",IF(OR(PricePerOunce[[#This Row],[2018]]>PricePerOunce[[#This Row],[2016]],PricePerOunce[[#This Row],[2018]]>AVERAGE(PricePerOunce[[#This Row],[2013]:[2016]])),"Increase","Decrease")) -> Increase
A8: Cincinnati Reds | B8: 0.46 | C8: 0.46 | D8: 0.46 | E8: 0.38 | F8: 0.45 | G8: =IF(PricePerOunce[[#This Row],[2018]]=PricePerOunce[[#This Row],[2013]],"None",IF(OR(PricePerOunce[[#This Row],[2018]]>PricePerOunce[[#This Row],[2016]],PricePerOunce[[#This Row],[2018]]>AVERAGE(PricePerOunce[[#This Row],[2013]:[2016]])),"Increase","Decrease")) -> Increase
A9: Cleveland Indians | B9: 0.33 | C9: 0.33 | D9: 0.33 | E9: 0.33 | F9: 0.42 | G9: =IF(PricePerOunce[[#This Row],[2018]]=PricePerOunce[[#This Row],[2013]],"None",IF(OR(PricePerOunce[[#This Row],[2018]]>PricePerOunce[[#This Row],[2016]],PricePerOunce[[#This Row],[2018]]>AVERAGE(PricePerOunce[[#This Row],[2013]:[2016]])),"Increase","Decrease")) -> Increase
A10: Colorado Rockies | B10: 0.38 | C10: 0.38 | D10: 0.38 | E10: 0.25 | F10: 0.25 | G10: =IF(PricePerOunce[[#This Row],[2018]]=PricePerOunce[[#This Row],[2013]],"None",IF(OR(PricePerOunce[[#This Row],[2018]]>PricePerOunce[[#This Row],[2016]],PricePerOunce[[#This Row],[2018]]>AVERAGE(PricePerOunce[[#This Row],[2013]:[2016]])),"Increase","Decrease")) -> Decrease
A11: Detroit Tigers | B11: 0.42 | C11: 0.42 | D11: 0.42 | E11: 0.42 | F11: 0.42 | G11: =IF(PricePerOunce[[#This Row],[2018]]=PricePerOunce[[#This Row],[2013]],"None",IF(OR(PricePerOunce[[#This Row],[2018]]>PricePerOunce[[#This Row],[2016]],PricePerOunce[[#This Row],[2018]]>AVERAGE(PricePerOunce[[#This Row],[2013]:[2016]])),"Increase","Decrease")) -> None
A12: Houston Astros | B12: 0.36 | C12: 0.36 | D12: 0.36 | E12: 0.36 | F12: 0.43 | G12: =IF(PricePerOunce[[#This Row],[2018]]=PricePerOunce[[#This Row],[2013]],"None",IF(OR(PricePerOunce[[#This Row],[2018]]>PricePerOunce[[#This Row],[2016]],PricePerOunce[[#This Row],[2018]]>AVERAGE(PricePerOunce[[#This Row],[2013]:[2016]])),"Increase","Decrease")) -> Increase
A13: Kansas City Royals | B13: 0.41 | C13: 0.41 | D13: 0.41 | E13: 0.41 | F13: 0.33 | G13: =IF(PricePerOunce[[#This Row],[2018]]=PricePerOunce[[#This Row],[2013]],"None",IF(OR(PricePerOunce[[#This Row],[2018]]>PricePerOunce[[#This Row],[2016]],PricePerOunce[[#This Row],[2018]]>AVERAGE(PricePerOunce[[#This Row],[2013]:[2016]])),"Increase","Decrease")) -> Decrease
... A31: Washington Nationals | B31: 0.52 | C31: 0.41 | D31: 0.41 | E31: 0.41 | F31: 0.5 | G31: =IF(PricePerOunce[[#This Row],[2018]]=PricePerOunce[[#This Row],[2013]],"None",IF(OR(PricePerOunce[[#This Row],[2018]]>PricePerOunce[[#This Row],[2016]],PricePerOunce[[#This Row],[2018]]>AVERAGE(PricePerOunce[[#This Row],[2013]:[2016]])),"Increase","Decrease")) -> Increase

Sheet PROJECT 3

Sheet Indicators
A1: Country | B1: Region | C1: Population | D1: Area
A2: Afghanistan | B2: South Asia | C2: 38041754 | D2: 652230
A3: Albania | B3: Europe & Central Asia | C3: 2854191 | D3: 28748
A4: Algeria | B4: Middle East & North Africa | C4: 43053054 | D4: 2381741
A5: Andorra | B5: Europe & Central Asia | C5: 77142 | D5: 468
A6: Angola | B6: Sub-Saharan Africa | C6: 31825295 | D6: 1246700
A7: Antigua and Barbuda | B7: Latin America & Caribbean | C7: 97118 | D7: 442.6
A8: Argentina | B8: Latin America & Caribbean | C8: 44938712 | D8: 2780400
A9: Armenia | B9: Europe & Central Asia | C9: 2957731 | D9: 29743
A10: Australia | B10: East Asia & Pacific | C10: 25364307 | D10: 7741220
A11: Austria | B11: Europe & Central Asia | C11: 8877067 | D11: 83871
A12: Azerbaijan | B12: Europe & Central Asia | C12: 10023318 | D12: 86600
A13: Bahrain | B13: Middle East & North Africa | C13: 1641172 | D13: 765.3
... A182: Zimbabwe | B182: Sub-Saharan Africa | C182: 14645468 | D182: 390757

Sheet Region Summary
A3: Region | B3: Sum of Population | C3: Sum of Area | D3: Sum of Population Density
A4: East Asia & Pacific | B4: 2285279040 | C4: 24434902 | D4: 93.525197
A5: South Asia | B5: 1835776742 | C5: 5135531 | D5: 357.46581
A6: Sub-Saharan Africa | B6: 1049530538 | C6: 21646744 | D6: 48.484453
A7: Europe & Central Asia | B7: 918863253 | C7: 28062555 | D7: 32.743393
A8: Latin America & Caribbean | B8: 606875478 | C8: 19416627 | D8: 31.255453
A9: North America | B9: 365828785 | C9: 19818187 | D9: 18.459246
A10: Middle East & North Africa | B10: 352038057 | C10: 9436163.3 | D10: 37.30733
A11: Grand Total | B11: 7414191893 | C11: 1.2795071e+08 | D11: 57.945688

Sheet PROJECT 4

Sheet Inventory
A1: Country | B1: Province | C1: Winery | D1: Variety | E1: Name | F1: Year | G1: Stock On Hand | H1: Reorder Quantity | I1: Price
A2: France | B2: Bordeaux | C2: Cheval Quancard | D2: Bordeaux Red | E2: Cheval Quancard (2009) Chai de Bordes | F2: 2009 | G2: 26 | H2: 15 | I2: 10
A3: France | B3: Bordeaux | C3: Cheval Quancard | D3: Bordeaux Red | E3: Cheval Quancard (2009) Monfort Bellevue | F3: 2009 | G3: 50 | H3: 10 | I3: 22
A4: France | B4: Bordeaux | C4: Cheval Quancard | D4: Bordeaux Red | E4: Cheval Quancard (2010) Chai de Bordes | F4: 2010 | G4: 34 | H4: 15 | I4: 12
A5: France | B5: Bordeaux | C5: Cheval Quancard | D5: Bordeaux Red | E5: Cheval Quancard (2010) Fleur de Roc | F5: 2010 | G5: 15 | H5: 10 | I5: 20
A6: France | B6: Bordeaux | C6: Cheval Quancard | D6: Bordeaux Red | E6: Cheval Quancard (2010) Prestige de Bordes | F6: 2010 | G6: 28 | H6: 15 | I6: 13
A7: France | B7: Bordeaux | C7: Cheval Quancard | D7: Bordeaux Red | E7: Cheval Quancard (2012) Chai de Bordes | F7: 2012 | G7: 36 | H7: 15 | I7: 12
A8: France | B8: Bordeaux | C8: Cheval Quancard | D8: Bordeaux Red | E8: Cheval Quancard (2014) Chai de Bordes | F8: 2014 | G8: 42 | H8: 15 | I8: 12
A9: France | B9: Bordeaux | C9: Cheval Quancard | D9: Bordeaux Red | E9: Cheval Quancard (2014) Fortin Plaisance | F9: 2014 | G9: 16 | H9: 10 | I9: 20
A10: France | B10: Bordeaux | C10: Cheval Quancard | D10: Bordeaux Red | E10: Cheval Quancard (2014) Monfort Bellevue | F10: 2014 | G10: 25 | H10: 15 | I10: 17
A11: France | B11: Bordeaux | C11: Cheval Quancard | D11: Bordeaux Red | E11: Cheval Quancard (2015) Chai de Bordes | F11: 2015 | G11: 31 | H11: 15 | I11: 13
A12: France | B12: Bordeaux | C12: Cheval Quancard | D12: Bordeaux Red | E12: Cheval Quancard (2015) Fleur du Roc | F12: 2015 | G12: 22 | H12: 10 | I12: 25
A13: France | B13: Burgundy | C13: Louis Latour | D13: Chardonnay | E13: Louis Latour (2008) Batard-Montrachet | F13: 2008 | G13: 36 | H13: 0 | I13: 255
... A101: US | B101: Washington | C101: Canoe Ridge | D101: Merlot | E101: Canoe Ridge (2014) The Expedition | F101: 2014 | G101: 25 | H101: 15 | I101: 15

Sheet Order Tracker
A1: Order Tracker
A2: Order ID: | B2: 555-123
A3: Purchase Date: | B3: 44149
A4: Shipment Time (business days): | B4: 12
A5: Arrival Date: | B5: =WORKDAY(B3,B4) -> 44166

Sheet PROJECT 5

Sheet Product Sales
A1: Product ID | B1: Product Group | C1: Product Category | D1: Product Type | E1: Product Name | F1: Units Sold | G1: Total Sales
A2: 63 | B2: Add-ons | C2: Flavours | D2: Regular syrup | E2: Carmel syrup | F2: 15458 | G2: 12366.4
A3: 64 | B3: Add-ons | C3: Flavours | D3: Regular syrup | E3: Hazelnut syrup | F3: 14552 | G3: 11641.6
A4: 65 | B4: Add-ons | C4: Flavours | D4: Sugar free syrup | E4: Sugar Free Vanilla syrup | F4: 17764 | G4: 14211.2
A5: 84 | B5: Add-ons | C5: Flavours | D5: Regular syrup | E5: Chocolate syrup | F5: 16051 | G5: 12840.8
B6: Add-ons Total | F6: =SUBTOTAL(9,F2:F5) -> 63825 | G6: =SUBTOTAL(9,G2:G5) -> 51060
A7: 22 | B7: Beverages | C7: Coffee | D7: Drip coffee | E7: Our Old Time Diner Blend Sm | F7: 26768 | G7: 53536
A8: 23 | B8: Beverages | C8: Coffee | D8: Drip coffee | E8: Our Old Time Diner Blend Rg | F8: 26831 | G8: 67077.5
A9: 24 | B9: Beverages | C9: Coffee | D9: Drip coffee | E9: Our Old Time Diner Blend Lg | F9: 24888 | G9: 74664
A10: 25 | B10: Beverages | C10: Coffee | D10: Organic brewed coffee | E10: Brazilian Sm | F10: 26671 | G10: 58676.2
A11: 26 | B11: Beverages | C11: Coffee | D11: Organic brewed coffee | E11: Brazilian Rg | F11: 26852 | G11: 80556
A12: 27 | B12: Beverages | C12: Coffee | D12: Organic brewed coffee | E12: Brazilian Lg | F12: 26001 | G12: 91003.5
A13: 28 | B13: Beverages | C13: Coffee | D13: Gourmet brewed coffee | E13: Columbian Medium Roast Sm | F13: 25236 | G13: 50472
A14: 29 | B14: Beverages | C14: Coffee | D14: Gourmet brewed coffee | E14: Columbian Medium Roast Rg | F14: 27514 | G14: 68785
A15: 30 | B15: Beverages | C15: Coffee | D15: Gourmet brewed coffee | E15: Columbian Medium Roast Lg | F15: 25970 | G15: 77910
A16: 31 | B16: Beverages | C16: Coffee | D16: Gourmet brewed coffee | E16: Ethiopia Sm | F16: 27061 | G16: 59534.2
A17: 32 | B17: Beverages | C17: Coffee | D17: Gourmet brewed coffee | E17: Ethiopia Rg | F17: 27287 | G17: 81861
A18: 33 | B18: Beverages | C18: Coffee | D18: Gourmet brewed coffee | E18: Ethiopia Lg | F18: 26146 | G18: 91511
... A47: 87 | B47: Beverages | C47: Coffee | D47: Barista Espresso | E47: Ouro Brasileiro shot | F47: 19967 | G47: 59901
B48: Beverages Total | F48: =SUBTOTAL(9,F7:F47) -> 1074391 | G48: =SUBTOTAL(9,G7:G47) -> 3287622.9
A49: 69 | B49: Food | C49: Bakery | D49: Biscotti | E49: Hazelnut Biscotti | F49: 12290 | G49: 43015
A50: 70 | B50: Food | C50: Bakery | D50: Scone | E50: Cranberry Scone | F50: 12549 | G50: 40784.25
A51: 71 | B51: Food | C51: Bakery | D51: Pastry | E51: Chocolate Croissant | F51: 19213 | G51: 72048.75
A52: 72 | B52: Food | C52: Bakery | D52: Scone | E52: Ginger Scone | F52: 15845 | G52: 51496.25
A53: 73 | B53: Food | C53: Bakery | D53: Pastry | E53: Almond Croissant | F53: 11753 | G53: 44073.75
A54: 74 | B54: Food | C54: Bakery | D54: Biscotti | E54: Ginger Biscotti | F54: 11007 | G54: 38524.5
A55: 75 | B55: Food | C55: Bakery | D55: Pastry | E55: Croissant | F55: 11837 | G55: 38470.25
A56: 76 | B56: Food | C56: Bakery | D56: Biscotti | E56: Chocolate Chip Biscotti | F56: 11571 | G56: 40498.5
A57: 77 | B57: Food | C57: Bakery | D57: Scone | E57: Oatmeal Scone | F57: 11065 | G57: 33195
A58: 78 | B58: Food | C58: Bakery | D58: Scone | E58: Scottish Cream Scone | F58: 11837 | G58: 53266.5
A59: 79 | B59: Food | C59: Bakery | D59: Scone | E59: Jumbo Savory Scone | F59: 12466 | G59: 46747.5
B60: Food Total | F60: =SUBTOTAL(9,F49:F59) -> 141433 | G60: =SUBTOTAL(9,G49:G59) -> 502120.25
A61: 81 | B61: Merchandise | C61: Branded | D61: Clothing | E61: I Need My Bean! T-shirt | F61: 1429 | G61: 40012
A62: 82 | B62: Merchandise | C62: Branded | D62: Housewares | E62: I Need My Bean! Diner mug | F62: 1385 | G62: 16620
A63: 83 | B63: Merchandise | C63: Branded | D63: Housewares | E63: I Need My Bean! Latte cup | F63: 1883 | G63: 26362
B64: Merchandise Total | F64: =SUBTOTAL(9,F61:F63) -> 4697 | G64: =SUBTOTAL(9,G61:G63) -> 82994
A65: 1 | B65: Whole Bean/Teas | C65: Coffee beans | D65: Organic Beans | E65: Brazilian - Organic | F65: 1289 | G65: 23202
A66: 2 | B66: Whole Bean/Teas | C66: Coffee beans | D66: House blend Beans | E66: Our Old Time Diner Blend | F66: 1186 | G66: 21348
A67: 3 | B67: Whole Bean/Teas | C67: Coffee beans | D67: Espresso Beans | E67: Espresso Roast | F67: 988 | G67: 14573
A68: 4 | B68: Whole Bean/Teas | C68: Coffee beans | D68: Espresso Beans | E68: Primo Espresso Roast | F68: 891 | G68: 18220.95
...

Sheet Sales by Store
A1: Astoria Store | G1: NYC Totals
A2: Product Group | B2: Q1 | C2: Q2 | D2: Q3 | E2: Q4 | G2: Product Group | H2: Q1 | I2: Q2 | J2: Q3 | K2: Q4
A3: Beverages | B3: 108110.9 | C3: 131578.3 | D3: 126159.05 | E3: 140993.25 | G3: Beverages | H3: 316404.05 | I3: 383907.3 | J3: 367838.75 | K3: 412387.65
A4: Food | B4: 15699.75 | C4: 19002.75 | D4: 18172.5 | E4: 20247.5 | G4: Food | H4: 48326.94 | I4: 58639.84 | J4: 56064.76 | K4: 62821.58
A5: Whole Bean/Teas | B5: 8926.53 | C5: 10767.76 | D5: 10171.4 | E5: 11000.11 | G5: Whole Bean/Teas | H5: 31288.05 | I5: 38990.32 | J5: 37774.97 | K5: 41339.94
A6: Merchandise | B6: 3248 | C6: 3829 | D6: 3779 | E6: 4371 | G6: Merchandise | H6: 7794 | I6: 9869 | J6: 9213 | K6: 10827
A7: Add-ons | B7: 1075.2 | C7: 1259.2 | D7: 1220.8 | E7: 1396 | G7: Add-ons | H7: 4977.6 | I7: 5980.8 | J7: 5686.4 | K7: 6412.8
A8: Grand Total | B8: 137060.38 | C8: 166437.01 | D8: 159502.75 | E8: 178007.86 | G8: Grand Total | H8: 408790.64 | I8: 497387.26 | J8: 476577.88 | K8: 533788.97
A10: Lower Manhattan Store
A11: Product Group | B11: Q1 | C11: Q2 | D11: Q3 | E11: Q4
A12: Beverages | B12: 104200.2 | C12: 125505.05 | D12: 121090.95 | E12: 134841.15
A13: Food | B13: 16615.79 | C13: 20265.94 | D13: 19442.16 | E13: 21688.63
A14: Whole Bean/Teas | B14: 9852.74 | C14: 11884.09 | D14: 11037.1 | E14: 12762.77
A15: Merchandise | B15: 3640 | C15: 4718 | D15: 4484 | E15: 4986
A16: Add-ons | B16: 2272 | C16: 2735.2 | D16: 2592.8 | E16: 2908
A17: Grand Total | B17: 136580.73 | C17: 165108.28 | D17: 158647.01 | E17: 177186.55
A19: Hell's Kitchen Store
A20: Product Group | B20: Q1 | C20: Q2 | D20: Q3 | E20: Q4
A21: Beverages | B21: 104092.95 | C21: 126823.95 | D21: 120588.75 | E21: 136553.25
A22: Food | B22: 16011.4 | C22: 19371.15 | D22: 18450.1 | E22: 20885.45
A23: Whole Bean/Teas | B23: 12508.78 | C23: 16338.47 | D23: 16566.47 | E23: 17577.06
A24: Add-ons | B24: 1630.4 | C24: 1986.4 | D24: 1872.8 | E24: 2108.8
A25: Merchandise | B25: 906 | C25: 1322 | D25: 950 | E25: 1470
A26: Grand Total | B26: 135149.53 | C26: 165841.97 | D26: 158428.12 | E26: 178594.56

Sheet New Product
A1: Rocky Roast Premium Beans
A2: Fixed Costs: | B2: 250
A3: Variable Costs: | B3: 16.5
A4: Price: | B4: 22
A6: Units Sold: | B6: 590.90909
A8: Profit: | B8: =IFERROR((B4-B3)*B6-B2,"") -> 3000

Sheet PROJECT 6

Sheet Van Collisions
A1: Van Collisions in NYC
A2: Date | B2: Time | C2: District | D2: Collision Cause | E2: Vehicle | F2: # of Persons Injured
A3: 43832 | B3: 0.76041667 | C3: Manhattan | D3: Passing Too Closely | E3: Bus | F3: 0
A4: 43833 | B4: 0.47222222 | C4: Brooklyn | D4: Passing Too Closely | E4: Sedan | F4: 0
A5: 43833 | B5: 0.54166667 | C5: Bronx | D5: Unspecified | E5: Bike | F5: 1
A6: 43834 | B6: 0.20486111 | C6: Queens | D6: Brakes Defective | E6: Station Wagon | F6: 0
A7: 43834 | B7: 0.46319444 | C7: Brooklyn | D7: Following Too Closely | E7: Van | F7: 0
A8: 43835 | B8: 0.40208333 | C8: Brooklyn | D8: Driver Inattention/Distraction | E8: Sedan | F8: 0
A9: 43835 | B9: 0.65277778 | C9: Brooklyn | D9: Passing Too Closely | E9: Station Wagon | F9: 0
A10: 43836 | B10: 0.44097222 | C10: Brooklyn | D10: Driver Inattention/Distraction | E10: Sedan | F10: 0
A11: 43837 | B11: 0.69097222 | C11: Brooklyn | D11: Driver Inexperience | E11: Trailer | F11: 0
A12: 43838 | B12: 0.47222222 | C12: Brooklyn | D12: Driver Inattention/Distraction | E12: Station Wagon | F12: 0
A13: 43839 | B13: 0.43402778 | C13: Brooklyn | D13: Passing or Lane Usage Improper | E13: Station Wagon | F13: 0
A14: 43839 | B14: 0.4375 | C14: Brooklyn | D14: Brakes Defective | E14: Box Truck | F14: 0
... A201: 44034 | B201: 0.70486111 | C201: Manhattan | D201: Driver Inattention/Distraction | E201: Sedan | F201: 1

Sheet Taxi Collisions
A1: Taxi Collisions in NYC
A2: Date | B2: Time | C2: District | D2: Collision Cause | E2: Vehicle | F2: # of Persons Injured
A3: 43831 | B3: 0.1 | C3: Bronx | D3: Driver Inattention/Distraction | E3: Taxi | F3: 3
A4: 43833 | B4: 0.22222222 | C4: Manhattan | D4: Driver Inattention/Distraction | E4: Pick-up Truck | F4: 1
A5: 43834 | B5: 0.19583333 | C5: Manhattan | D5: Driver Inattention/Distraction | E5: Sedan | F5: 0
A6: 43835 | B6: 0.28333333 | C6: Bronx | D6: Traffic Control Disregarded | E6: Sedan | F6: 2
A7: 43835 | B7: 0.33333333 | C7: Queens | D7: Passing Too Closely | E7: Taxi | F7: 0
A8: 43835 | B8: 0.71180556 | C8: Manhattan | D8: Other Vehicular | E8: Sedan | F8: 0
A9: 43837 | B9: 0.875 | C9: Brooklyn | D9: Passing or Lane Usage Improper | E9: Sedan | F9: 0
A10: 43838 | B10: 0.75 | C10: Brooklyn | D10: Driver Inattention/Distraction | E10: Sedan | F10: 0
A11: 43838 | B11: 0.94375 | C11: Bronx | D11: Other Vehicular | E11: Sedan | F11: 0
A12: 43839 | B12: 0.0013888889 | C12: Manhattan | D12: Traffic Control Disregarded | E12: Sedan | F12: 1
A13: 43839 | B13: 0.58333333 | C13: Manhattan | D13: Driver Inattention/Distraction | E13: Bike | F13: 0
A14: 43840 | B14: 0.54861111 | C14: Manhattan | D14: Unsafe Lane Changing | E14: Van | F14: 0
... A151: 44023 | B151: 0.92986111 | C151: Manhattan | D151: Pedestrian/Bicyclist/Other Pedestrian Error/Confusion | E151: Bike | F151: 1

Sheet Monthly Trend
A1: Month | B1: Collisions | C1: Injury %
A2: Jan | B2: 9506 | C2: 0.21992021
A3: Feb | B3: 8986 | C3: 0.22193803
A4: Mar | B4: 7241 | C4: 0.21524826
A5: Apr | B5: 2598 | C5: 0.24562682
A6: May | B6: 3953 | C6: 0.304765
A7: Jun | B7: 5012 | C7: 0.35596113
A8: Jul | B8: 6128 | C8: 0.34731707
A9: Aug | B9: 5716 | C9: 0.35006288

Sheet Collision Causes
A3: Collision Cause | B3: Sum of # of Persons Injured
A4: Driver Inattention/Distraction | B4: 0.51785714
A5: Other Vehicular | B5: 0.14285714
A6: Traffic Control Disregarded | B6: 0.089285714
A7: Pedestrian/Bicyclist/Other Pedestrian Error/Confusion | B7: 0.071428571
A8: Unsafe Lane Changing | B8: 0.053571429
A9: Following Too Closely | B9: 0.035714286
A10: Driver Inexperience | B10: 0.035714286
A11: Failure to Yield Right-of-Way | B11: 0.017857143
A12: Turning Improperly | B12: 0.017857143
A13: View Obstructed/Limited | B13: 0.017857143
A14: Passing Too Closely | B14: 0
A15: Reaction to Uninvolved Vehicle | B15: 0
... A22: Grand Total | B22: 1
